Workbook

Sheet query
A1: SELECT a.traceid, -- date_format(from_unixtime(CAST(CAST(a.`timestamp` AS BIGINT) / 1000 AS BIGINT)), 'yyyy:MM:dd HH:mm:ss') AS time_stamp, a.hitidlist, z.p365d_user_completion_rate, z.p365d_user_complete_count, CASE CAST(z.country AS INT) WHEN 1000 THEN 'China' WHEN 10000 THEN 'India' WHEN 20000 THEN 'Brazil' WHEN 30000 THEN 'Singapore' WHEN 40000 THEN 'Malaysia' WHEN 50000 THEN 'Philippines' WHEN 60000 THEN 'Mexico' WHEN 70000 THEN 'United States of America' WHEN 80000 THEN 'Taiwan' WHEN 90000 THEN 'Hong Kong' WHEN 100000 THEN 'Vietnam' WHEN 110000 THEN 'Thailand' WHEN 120000 THEN 'Indonesia' WHEN 130000 THEN 'Bangladesh' WHEN 150000 THEN 'Japan' WHEN 160000 THEN 'Turkey' WHEN 170000 THEN 'United Arab Emirates' ELSE NULL END AS country_name, z.user_live_days, z.cancellation_rate, z.user_id_str, z.is_API_corp, z.ep_id, z.model, z.brand, z.is_enterprise_corp, z.ip, -- City Name Mapping from city_id_str CASE CAST(z.city_id_str AS INT) WHEN 101001 THEN 'Hanoi' WHEN 101002 THEN 'Ho Chi Minh City' WHEN 101003 THEN 'Haiphong' WHEN 101004 THEN 'Da Nang' WHEN 101005 THEN 'Can Tho' WHEN 101006 THEN 'Thai Nguyen' WHEN 31001 THEN 'Singapore' WHEN 41001 THEN 'Kuala Lumpur' WHEN 41002 THEN 'Penang' WHEN 41003 THEN 'Johor Bahru' WHEN 41004 THEN 'Malacca' WHEN 41005 THEN 'Kuching' WHEN 41006 THEN 'East Coast' WHEN 51001 THEN 'Manila' WHEN 51002 THEN 'Cebu' WHEN 51003 THEN 'Pampanga' WHEN 51004 THEN 'Cagayan' WHEN 51005 THEN 'Davao' WHEN 51006 THEN 'Iloilo' WHEN 51007 THEN 'Bacolod' WHEN 111001 THEN 'Bangkok' WHEN 111003 THEN 'Chonburi' WHEN 111004 THEN 'Khon Kaen' WHEN 111005 THEN 'Chiang Mai' WHEN 121001 THEN 'Jakarta' WHEN 121002 THEN 'Bandung' WHEN 121003 THEN 'Surabaya' WHEN 121004 THEN 'Cirebon' WHEN 121005 THEN 'Malang' WHEN 121007 THEN 'Semarang' WHEN 121008 THEN 'Yogyakarta' WHEN 121009 THEN 'Medan' WHEN 131001 THEN 'Dhaka' WHEN 151001 THEN 'Tokyo' WHEN 151002 THEN 'Kansai' WHEN 161001 THEN 'Istanbul' WHEN 171001 THEN 'Dubai' WHEN 171002 THEN 'Sharjah' WHEN 171003 THEN 'Abu Dhabi' WHEN 171004 THEN 'Ajman' WHEN 181001 THEN 'Riyadh' WHEN 81001 THEN 'Taipei' WHEN 81002 THEN 'Taichung' WHEN 81003 THEN 'Kaohsiung' WHEN 81004 THEN 'Tainan' WHEN 81005 THEN 'Hualien' WHEN 91001 THEN 'Hong Kong' WHEN 21001 THEN 'Sao Paulo' WHEN 21002 THEN 'Rio de Janeiro' WHEN 21003 THEN 'Belo Horizonte' WHEN 21004 THEN 'Curitiba' WHEN 21005 THEN 'Porto Alegre' WHEN 21006 THEN 'Brasília' WHEN 21007 THEN 'Goiânia' WHEN 21008 THEN 'Salvador' WHEN 21009 THEN 'Recife' WHEN 21010 THEN 'Fortaleza' WHEN 21011 THEN 'Aracaju' WHEN 21012 THEN 'Belém' WHEN 21013 THEN 'Florianópolis' WHEN 21014 THEN 'Ribeirão Preto' WHEN 21015 THEN 'Maceió' WHEN 21016 THEN 'São Luís' WHEN 21017 THEN 'Manaus' WHEN 21018 THEN 'Campinas' WHEN 61001 THEN 'Mexico City' ELSE 'Other / Unknown' END AS city_name, z.is_VN_first_login_city, z.reg_datetime -- date_format(from_unixtime(CAST(CAST(z.reg_time AS BIGINT) / 1000 AS BIGINT)), 'yyyy:MM:dd HH:mm:ss') AS reg_time_formatted FROM llm_dwd.dwd_risk_avira_event_1d_in_view a LATERAL VIEW json_tuple( a.snapshot, 'p365d_user_completion_rate', 'p365d_user_complete_count', 'country', 'user_live_days', 'cancellation_rate', 'user_id_str', 'is_API_corp', 'ep_id', 'model', 'brand', 'is_enterprise_corp', 'ip', 'city_id_str', 'is_VN_first_login_city', 'reg_datetime' -- 'reg_time' ) z AS p365d_user_completion_rate, p365d_user_complete_count, country, user_live_days, cancellation_rate, user_id_str, is_API_corp, ep_id, model, brand, is_enterprise_corp, ip, city_id_str, is_VN_first_login_city, reg_datetime -- reg_time WHERE a.dt BETWEEN '2026-09-29' AND '2026-10-07' AND a.hitidlist IS NOT NULL -- Matches standalone ID 1254 safely at the start, middle, or end of hitidlist AND a.hitidlist RLIKE '(^|[^0-9])1254([^0-9]|$)' -- Vietnam Market Filter AND z.country = 100000;

Sheet Results export
A1: traceid | B1: hitidlist | C1: p365d_user_completion_rate | D1: p365d_user_complete_count | E1: country_name | F1: user_live_days | G1: cancellation_rate | H1: user_id_str | I1: is_api_corp | J1: ep_id | K1: model | L1: brand | M1: is_enterprise_corp | N1: ip | O1: city_name | P1: is_vn_first_login_city | Q1: reg_datetime
A2: ad0fb0ff856dbe36.101.17912750714410706 | B2: [1254] | C2: 0.14371002 | D2: 337 | E2: Vietnam | F2: 2350 | G2: 0.890625 | H2: 8200826 | I2: false | J2: 922514082 | K2: iPhone17 Pro Max | M2: false | N2: 127.0.0.1 | O2: Hanoi | P2: true | Q2: 2020-04-30 15:05:10
A3: ad0fb0ff856dbe36.101.17912752031510872 | B3: [1254] | C3: 0.14371002 | D3: 337 | E3: Vietnam | F3: 2350 | G3: 0.89230769 | H3: 8200826 | I3: false | J3: 922514082 | K3: iPhone17 Pro Max | M3: false | N3: 127.0.0.1 | O3: Hanoi | P3: true | Q3: 2020-04-30 15:05:10
A4: ad0fb0ff856dbe36.101.17912752200470954 | B4: [1254] | C4: 0.14371002 | D4: 337 | E4: Vietnam | F4: 2350 | G4: 0.87878788 | H4: 8200826 | I4: false | J4: 922514082 | K4: iPhone17 Pro Max | M4: false | N4: 127.0.0.1 | O4: Hanoi | P4: true | Q4: 2020-04-30 15:05:10
A5: ad0fb0ff856dbe36.101.17912754060621062 | B5: [1254] | C5: 0.14371002 | D5: 337 | E5: Vietnam | F5: 2350 | G5: 0.87878788 | H5: 8200826 | I5: false | J5: 922514082 | K5: iPhone17 Pro Max | M5: false | N5: 127.0.0.1 | O5: Hanoi | P5: true | Q5: 2020-04-30 15:05:10
A6: ad0fb0ff856dbe36.101.17912754169101136 | B6: [1254] | C6: 0.14371002 | D6: 337 | E6: Vietnam | F6: 2350 | G6: 0.86567164 | H6: 8200826 | I6: false | J6: 922514082 | K6: iPhone17 Pro Max | M6: false | N6: 127.0.0.1 | O6: Hanoi | P6: true | Q6: 2020-04-30 15:05:10
A7: 8fc1cf6c10de646a.101.17912761541420802 | B7: [1254] | C7: 0 | D7: 0 | E7: Vietnam | F7: 22 | G7: 0.91666667 | H7: 44465314 | I7: false | J7: 0 | K7: iPhone 15 Pro Max | M7: false | N7: 127.0.0.1 | O7: Hanoi | P7: true | Q7: 2026-09-14 08:30:46
A8: 95a5e059d53424d3.101.17913396788571255 | B8: [1254] | C8: 0.14309835 | D8: 339 | E8: Vietnam | F8: 2351 | G8: 0.77272727 | H8: 8200826 | I8: false | J8: 922514082 | K8: iPhone17 Pro Max | M8: false | N8: 127.0.0.1 | O8: Hanoi | P8: true | Q8: 2020-04-30 15:05:10
A9: 95a5e059d53424d3.101.17913396883741329 | B9: [1254] | C9: 0.14309835 | D9: 339 | E9: Vietnam | F9: 2351 | G9: 0.76404494 | H9: 8200826 | I9: false | J9: 922514082 | K9: iPhone17 Pro Max | M9: false | N9: 127.0.0.1 | O9: Hanoi | P9: true | Q9: 2020-04-30 15:05:10
A10: 95a5e059d53424d3.101.17913397100101432 | B10: [1254] | C10: 0.14309835 | D10: 339 | E10: Vietnam | F10: 2351 | G10: 0.75555556 | H10: 8200826 | I10: false | J10: 922514082 | K10: iPhone17 Pro Max | M10: false | N10: 127.0.0.1 | O10: Hanoi | P10: true | Q10: 2020-04-30 15:05:10
A11: 95a5e059d53424d3.101.17913384893940676 | B11: [1254] | C11: 0.14309835 | D11: 339 | E11: Vietnam | F11: 2351 | G11: 0.82926829 | H11: 8200826 | I11: false | J11: 922514082 | K11: iPhone17 Pro Max | M11: false | N11: 127.0.0.1 | O11: Hanoi | P11: true | Q11: 2020-04-30 15:05:10
A12: 95a5e059d53424d3.101.17913385037960757 | B12: [1254] | C12: 0.14309835 | D12: 339 | E12: Vietnam | F12: 2351 | G12: 0.81927711 | H12: 8200826 | I12: false | J12: 922514082 | K12: iPhone17 Pro Max | M12: false | N12: 127.0.0.1 | O12: Hanoi | P12: true | Q12: 2020-04-30 15:05:10
A13: b6dd64368e28fb01.201.17912497393080836 | B13: [1254] | C13: 0 | D13: 0 | E13: Vietnam | F13: 1 | G13: 0 | H13: 45055754 | I13: false | J13: 0 | K13: Pixel | M13: false | N13: 127.0.0.1 | O13: Ho Chi Minh City | P13: true | Q13: 2026-10-05 15:28:58
... A57: 8543f31384dcb19b.101.17908149269150688 | B57: [1254] | C57: 0 | D57: 0 | E57: Vietnam | F57: 5 | G57: 0.57142857 | H57: 44795713 | I57: false | J57: 0 | K57: iPhone 11 Pro Max | M57: false | N57: 127.0.0.1 | O57: Hanoi | P57: true | Q57: 2026-09-26 14:04:17
A58: 2d6d0182abfa429791b54fb1e929ea98.356.17908600395352578 | B58: [1254] | C58: 0.15812432 | D58: 145 | E58: Vietnam | F58: 690 | G58: 0.8372093 | H58: 28625427 | I58: false | J58: 1192123022 | K58: NULL | L58: NULL | M58: false | N58: 127.0.0.1 | O58: Ho Chi Minh City | P58: true | Q58: 2024-11-10 16:14:40
A59: b951801133b1fbfb.201.17910743391230347 | B59: [1254] | C59: 0.012345679 | D59: 1 | E59: Vietnam | F59: 1 | G59: 0.13953488 | H59: 44986521 | I59: false | J59: 0 | K59: Pixel | M59: false | N59: 127.0.0.1 | O59: Ho Chi Minh City | P59: true | Q59: 2026-10-03 08:10:46
A60: b951801133b1fbfb.201.17910743763160401 | B60: [1254] | C60: 0.012345679 | D60: 1 | E60: Vietnam | F60: 1 | G60: 0.13793103 | H60: 44986521 | I60: false | J60: 0 | K60: Pixel | M60: false | N60: 127.0.0.1 | O60: Ho Chi Minh City | P60: true | Q60: 2026-10-03 08:10:46
A61: b951801133b1fbfb.201.17910744308540467 | B61: [1254] | C61: 0.012345679 | D61: 1 | E61: Vietnam | F61: 1 | G61: 0.13636364 | H61: 44986521 | I61: false | J61: 0 | K61: Pixel | M61: false | N61: 127.0.0.1 | O61: Ho Chi Minh City | P61: true | Q61: 2026-10-03 08:10:46
A62: a80e048a6057226b.101.17910137559301520 | B62: [1254] | C62: 0.14513351 | D62: 337 | E62: Vietnam | F62: 2347 | G62: 0.65116279 | H62: 8200826 | I62: false | J62: 922514082 | K62: iPhone17 Pro Max | M62: false | N62: 127.0.0.1 | O62: Hanoi | P62: true | Q62: 2020-04-30 15:05:10
A63: baab244b603c848c.201.17911608765240345 | B63: [1254] | C63: 0.011976048 | D63: 2 | E63: Vietnam | F63: 2 | G63: 0.29069767 | H63: 44986521 | I63: false | J63: 0 | K63: Pixel | M63: false | N63: 127.0.0.1 | O63: Ho Chi Minh City | P63: true | Q63: 2026-10-03 08:10:46
A64: baab244b603c848c.201.17911609043770401 | B64: [1254] | C64: 0.011976048 | D64: 2 | E64: Vietnam | F64: 2 | G64: 0.28901734 | H64: 44986521 | I64: false | J64: 0 | K64: Pixel | M64: false | N64: 127.0.0.1 | O64: Ho Chi Minh City | P64: true | Q64: 2026-10-03 08:10:46
A65: baab244b603c848c.201.17911609347420459 | B65: [1254] | C65: 0.011976048 | D65: 2 | E65: Vietnam | F65: 2 | G65: 0.28735632 | H65: 44986521 | I65: false | J65: 0 | K65: Pixel | M65: false | N65: 127.0.0.1 | O65: Ho Chi Minh City | P65: true | Q65: 2026-10-03 08:10:46
A66: baab244b603c848c.201.17911609637290523 | B66: [1254] | C66: 0.011976048 | D66: 2 | E66: Vietnam | F66: 2 | G66: 0.28571429 | H66: 44986521 | I66: false | J66: 0 | K66: Pixel | M66: false | N66: 127.0.0.1 | O66: Ho Chi Minh City | P66: true | Q66: 2026-10-03 08:10:46
A67: baab244b603c848c.201.17911610189650603 | B67: [1254] | C67: 0.011976048 | D67: 2 | E67: Vietnam | F67: 2 | G67: 0.28409091 | H67: 44986521 | I67: false | J67: 0 | K67: Pixel | M67: false | N67: 127.0.0.1 | O67: Ho Chi Minh City | P67: true | Q67: 2026-10-03 08:10:46
A68: b951801133b1fbfb.201.17910774595844760 | B68: [1254] | C68: 0.012345679 | D68: 1 | E68: Vietnam | F68: 1 | G68: 0.084507042 | H68: 44986521 | I68: false | J68: 0 | K68: Pixel | M68: false | N68: 127.0.0.1 | O68: Ho Chi Minh City | P68: true | Q68: 2026-10-03 08:10:46
A69: b951801133b1fbfb.201.17910774922304832 | B69: [1254] | C69: 0.012345679 | D69: 1 | E69: Vietnam | F69: 1 | G69: 0.083916084 | H69: 44986521 | I69: false | J69: 0 | K69: Pixel | M69: false | N69: 127.0.0.1 | O69: Ho Chi Minh City | P69: true | Q69: 2026-10-03 08:10:46
A70: b951801133b1fbfb.201.17910777026875075 | B70: [1254] | C70: 0.012345679 | D70: 1 | E70: Vietnam | F70: 1 | G70: 0.083333333 | H70: 44986521 | I70: false | J70: 0 | K70: Pixel | M70: false | N70: 127.0.0.1 | O70: Ho Chi Minh City | P70: true | Q70: 2026-10-03 08:10:46
... A102: bad08302cff50f33.201.17911644733030415 | B102: [1254] | C102: 0.011976048 | D102: 2 | E102: Vietnam | F102: 2 | G102: 0.25252525 | H102: 44986521 | I102: false | J102: 0 | K102: Pixel | M102: false | N102: 127.0.0.1 | O102: Ho Chi Minh City | P102: true | Q102: 2026-10-03 08:10:46
A103: 5a0662937287404ca4e04b9bca67dd0a.313.17906665038761008 | B103: [1254] | C103: 0.32288401 | D103: 103 | E103: Vietnam | F103: 396 | G103: 0 | H103: 34917006 | I103: false | J103: 0 | K103: NULL | L103: NULL | M103: false | N103: 127.0.0.1 | O103: Hanoi | P103: true | Q103: 2025-08-29 15:36:46
A104: 10a7f055dc194e408fcef3d802510c57.360.17906667495611120 | B104: [1254] | C104: 0.32288401 | D104: 103 | E104: Vietnam | F104: 396 | G104: 0 | H104: 34917006 | I104: false | J104: 0 | K104: NULL | L104: NULL | M104: false | N104: 127.0.0.1 | O104: Hanoi | P104: true | Q104: 2025-08-29 15:36:46
A105: 899131ed5ec7b965.101.17906701281490662 | B105: [1254] | C105: 0.146777 | D105: 337 | E105: Vietnam | F105: 2343 | G105: 0.8 | H105: 8200826 | I105: false | J105: 922514082 | K105: iPhone17 Pro Max | M105: false | N105: 127.0.0.1 | O105: Hanoi | P105: true | Q105: 2020-04-30 15:05:10
A106: 899131ed5ec7b965.101.17906701528520782 | B106: [1254] | C106: 0.146777 | D106: 337 | E106: Vietnam | F106: 2343 | G106: 0.80392157 | H106: 8200826 | I106: false | J106: 922514082 | K106: iPhone17 Pro Max | M106: false | N106: 127.0.0.1 | O106: Hanoi | P106: true | Q106: 2020-04-30 15:05:10
A107: b1a53ee3a05d2d13.101.17911875831881597 | B107: [1254] | C107: 0.18181818 | D107: 2 | E107: Vietnam | F107: 282 | G107: 0.57142857 | H107: 37669736 | I107: false | J107: 0 | K107: iPhone 14 Pro Max | M107: false | N107: 127.0.0.1 | O107: Hanoi | P107: true | Q107: 2025-12-27 15:58:03
A108: b1a53ee3a05d2d13.101.17911876122951623 | B108: [1254] | C108: 0.18181818 | D108: 2 | E108: Vietnam | F108: 282 | G108: 0.54545455 | H108: 37669736 | I108: false | J108: 0 | K108: iPhone 14 Pro Max | M108: false | N108: 127.0.0.1 | O108: Hanoi | P108: true | Q108: 2025-12-27 15:58:03
A109: a1386396e90bd947.101.17908450423590751 | B109: [1254] | C109: 0.1452732 | D109: 335 | E109: Vietnam | F109: 2345 | G109: 0.78947368 | H109: 8200826 | I109: false | J109: 922514082 | K109: iPhone17 Pro Max | M109: false | N109: 127.0.0.1 | O109: Hanoi | P109: true | Q109: 2020-04-30 15:05:10
A110: a1386396e90bd947.101.17908450624730827 | B110: [1254] | C110: 0.1452732 | D110: 335 | E110: Vietnam | F110: 2345 | G110: 0.76923077 | H110: 8200826 | I110: false | J110: 922514082 | K110: iPhone17 Pro Max | M110: false | N110: 127.0.0.1 | O110: Hanoi | P110: true | Q110: 2020-04-30 15:05:10
A111: 9f9580edc4d9c9eb.101.17910170995881035 | B111: [1254] | C111: 0.14513351 | D111: 337 | E111: Vietnam | F111: 2347 | G111: 0.67346939 | H111: 8200826 | I111: false | J111: 922514082 | K111: iPhone17 Pro Max | M111: false | N111: 127.0.0.1 | O111: Hanoi | P111: true | Q111: 2020-04-30 15:05:10
A112: 9f9580edc4d9c9eb.101.17910171194861118 | B112: [1254] | C112: 0.14513351 | D112: 337 | E112: Vietnam | F112: 2347 | G112: 0.66 | H112: 8200826 | I112: false | J112: 922514082 | K112: iPhone17 Pro Max | M112: false | N112: 127.0.0.1 | O112: Hanoi | P112: true | Q112: 2020-04-30 15:05:10
A113: b97d9e545bce2564.101.17908350743850206 | B113: [1017,1254] | C113: 0 | D113: 0 | E113: Vietnam | F113: 249 | G113: 0.9 | H113: 38375955 | I113: false | J113: 0 | K113: iPhone X | M113: false | N113: 127.0.0.1 | O113: Hanoi | P113: true | Q113: 2026-01-25 20:00:04
A114: abd7b820f9e4e052.201.17907452550031653 | B114: [1254] | C114: 0 | D114: 0 | E114: Vietnam | F114: 16 | G114: 0.97938144 | H114: 44464690 | I114: false | J114: 1332325685 | K114: XPLORE 1 | M114: false | N114: 127.0.0.1 | O114: Hanoi | P114: true | Q114: 2026-09-14 07:49:03
...

Sheet unique_user info
A1: user_id | B1: register_time | C1: phone_no | D1: email | E1: last_name | F1: first_name | G1: city_id | H1: first_login_country | I1: total_create_cnt | J1: total_complete_cnt | K1: days_since_register | L1: first_create_time_local | M1: first_completed_order_time_local | N1: last_create_time_local | O1: last_complete_time_local | P1: is_corp | Q1: ban_status | R1: lifetime_completion_rate | S1: ban_reason | T1: ban_datetime
A2: 8200826 | B2: 2020-04-30 15:05:10 | C2: AES_DqKAiwkGfv8opG24IVeCuA== | D2: AES_DWRWcCotVf0lv/X2b3GSqbNV2XTl7G3vS91UHH/mnPw= | E2: Đại | F2: Huy | G2: 101001 | H2: 100000 | I2: 4252 | J2: 832 | K2: 2351 | L2: 2021-12-16 20:58:45 | M2: 2021-12-17 13:42:54 | N2: 2026-10-06 16:43:38 | O2: 2026-10-06 18:22:41 | P2: Corp | Q2: NOT BAN | R2: 0.19567262
A3: 44465314 | B3: 2026-09-14 08:30:46 | C3: AES_EG80BwxLXBc5gsIUr+RgzQ== | D3: AES_9KLxXiqNdWU672ajoJpJTnHW6OsU+dpF0iYwqr8bjhU= | G3: 101001 | H3: 100000 | I3: 17 | J3: 0 | K3: 23 | L3: 2026-09-28 12:35:45 | M3: NULL | N3: 2026-10-06 17:03:16 | O3: NULL | P3: No | Q3: NOT BAN | R3: 0
A4: 45055754 | B4: 2026-10-05 15:28:58 | C4: AES_7v36CSZECOTKF6X0j++5Zw== | D4: NULL | G4: 101002 | H4: 100000 | I4: 34 | J4: 1 | K4: 2 | L4: 2026-10-05 14:30:55 | M4: 2026-10-06 08:30:00 | N4: 2026-10-06 08:38:33 | O4: 2026-10-06 14:58:15 | P4: No | Q4: NOT BAN | R4: 0.029411765
A5: 45042918 | B5: 2026-10-05 08:41:36 | C5: AES_ix/FvG/7btkunwlUDnmqWg== | D5: NULL | G5: 101005 | H5: 100000 | I5: 27 | J5: 0 | K5: 2 | L5: 2026-10-05 07:43:51 | M5: NULL | N5: 2026-10-06 08:01:56 | O5: NULL | P5: No | Q5: BANNED | R5: 0 | S5: Placed over 20 fake orders | T5: 46301.467
A6: 44986521 | B6: 2026-10-03 08:10:46 | C6: AES_xwyzDKslXc9VZFphjS9mEQ== | D6: NULL | G6: 101002 | H6: 100000 | I6: 199 | J6: 2 | K6: 4 | L6: 2026-10-03 07:17:04 | M6: 2026-10-03 07:54:00 | N6: 2026-10-05 08:41:13 | O6: 2026-10-04 10:20:57 | P6: No | Q6: BANNED | R6: 0.010050251 | S6: Place over 200 fake orders | T6: 2026-10-05 10:11:24
A7: 44464690 | B7: 2026-09-14 07:49:03 | C7: AES_s/vbdxZq2e28WUoH7sGCDg== | D7: NULL | F7: ThiênDao | G7: 101001 | H7: 100000 | I7: 411 | J7: 0 | K7: 23 | L7: 2026-09-14 06:57:53 | M7: NULL | N7: 2026-10-01 07:54:17 | O7: NULL | P7: Corp | Q7: BANNED | R7: 0 | S7: Placed over 400 fake orders | T7: 2026-10-01 10:11:17
A8: 44795713 | B8: 2026-09-26 14:04:17 | C8: AES_XGYvrnJGAABTi9IWL0LieA== | D8: NULL | G8: 101001 | H8: 100000 | I8: 58 | J8: 0 | K8: 11 | L8: 2026-09-30 14:14:57 | M8: NULL | N8: 2026-10-01 14:49:30 | O8: NULL | P8: No | Q8: BANNED | R8: 0 | S8: Placed over 50 fake orders | T8: 2026-10-01 18:32:30
A9: 28625427 | B9: 2024-11-10 16:14:40 | C9: AES_XpZ/LaFoTNpmRUc7CnYG3g== | D9: AES_LWJW00rBiGwJcIdUU61eXCb28yKSv7myY4Ag5YbWx2U= | E9: Huỳnh | F9: Cô Kim | G9: 101002 | H9: 100000 | I9: 1210 | J9: 314 | K9: 696 | L9: 2024-11-26 14:07:25 | M9: 2024-11-26 14:43:10 | N9: 2026-10-06 16:48:00 | O9: 2026-10-04 13:15:16 | P9: Corp | Q9: NOT BAN | R9: 0.25950413
A10: 44643928 | B10: 2026-09-20 19:42:34 | C10: AES_IiT8y80Jnp/f8LfpZLCxow== | D10: NULL | G10: 101002 | H10: 100000 | I10: 45 | J10: 4 | K10: 17 | L10: 2026-09-20 18:45:41 | M10: 2026-09-20 19:06:00 | N10: 2026-10-02 15:54:14 | O10: 2026-10-01 12:14:29 | P10: No | Q10: NOT BAN | R10: 0.088888889
A11: 44003760 | B11: 2026-08-28 20:54:32 | C11: AES_V4dvC/sqXNn0qrnWJmmHMQ== | D11: AES_l8FfDv3IKtVsMGjerM0Iy/fOgr7Bs2FRt3/ptRK34Eo= | E11: Huyền | F11: Trần | G11: 101001 | H11: 100000 | I11: 28 | J11: 4 | K11: 40 | L11: 2026-08-28 19:55:25 | M11: 2026-09-25 14:15:07 | N11: 2026-10-05 15:09:50 | O11: 2026-10-02 17:55:50 | P11: No | Q11: NOT BAN | R11: 0.14285714
A12: 34917006 | B12: 2025-08-29 15:36:46 | C12: AES_L8tz9PT1VSTa4ryTtq7LsQ== | D12: AES_hPS73uQEDXVPHo5ViFgzHRZlYZDEw44o767790r1V50= | E12: gia bảo | F12: kho | G12: 101001 | H12: 100000 | I12: 324 | J12: 105 | K12: 404 | L12: 2025-08-29 14:49:19 | M12: 2025-11-28 15:38:05 | N12: 2026-10-01 09:28:21 | O12: 2026-10-01 10:37:35 | P12: No | Q12: NOT BAN | R12: 0.32407407
A13: 37669736 | B13: 2025-12-27 15:58:03 | C13: AES_qHC9MagdRDI62G0W6TMh+A== | D13: NULL | G13: 101001 | H13: 100000 | I13: 21 | J13: 2 | K13: 284 | L13: 2025-12-27 15:03:28 | M13: 2025-12-27 15:13:28 | N13: 2026-10-06 09:17:20 | O13: 2026-10-01 10:56:30 | P13: No | Q13: NOT BAN | R13: 0.095238095
A14: 38375955 | B14: 2026-01-25 20:00:04 | C14: AES_MilW1Wn8TQpjv/A3vZt8tQ== | D14: AES_VQXYyA5RCmojMUlw2W2HYKvB20Vjj3CSRyRfhnoOS20= | G14: 101001 | H14: 100000 | I14: 19 | J14: 0 | K14: 255 | L14: 2026-01-28 11:49:19 | M14: NULL | N14: 2026-10-01 13:13:34 | O14: NULL | P14: No | Q14: NOT BAN | R14: 0
A15: 40546651 | B15: 2026-04-21 16:48:03 | C15: AES_WZtVo8hdLFv15QVEovBdBA== | D15: AES_hHf1BAWfQGHEnmtbz679EcFdDX0vTrNcBbGS1f4xtnM= | E15: Thanh | F15: Van | G15: 101001 | H15: 100000 | I15: 51 | J15: 1 | K15: 169 | L15: 2026-05-07 05:08:04 | M15: 2026-08-27 08:51:45 | N15: 2026-10-04 11:53:18 | O15: 2026-08-27 10:32:17 | P15: No | Q15: NOT BAN | R15: 0.019607843
A16: 40007087 | B16: 2026-03-30 18:24:36 | C16: AES_1sgeR320aAvwJnXQmHD60Q== | D16: AES_j70m5TGl6uMXiiRnTJ/mGUsIf+EcNB1RMM1p6vN0gG8= | F16: Vĩnh Nghi | G16: 101002 | H16: 100000 | I16: 2 | J16: 0 | K16: 191 | L16: 2026-03-30 17:31:17 | M16: NULL | N16: 2026-10-04 16:18:44 | O16: NULL | P16: No | Q16: NOT BAN | R16: 0

Sheet reporting
A1: User Athena Link | B1: User ID | C1: Register time | D1: Status | E1: Corp? | F1: Flag order count | G1: Ban reason | H1: Ban date | I1: Account age (days) | J1: Lifetime_completion_rate | K1: TP/FP
A2: =HYPERLINK("https://sg-athena.lalamove.work/users/"&B2&"/overview?city_id=100000","User Athena") -> User Athena | B2: 8200826 | C2: 2020-04-30 15:05:10 | D2: NOT BAN | E2: Corp | F2: =COUNTIF('Results export'!$H$2:$H$202,reporting!B2) -> 23 | I2: =ROUNDUP(TODAY()-C2,0) -> 2352 | J2: 0.19567262 | K2: FP | N2: TP | O2: =COUNTIF($K$2:$K$16,N2) -> 12
A3: =HYPERLINK("https://sg-athena.lalamove.work/users/"&B3&"/overview?city_id=100000","User Athena") -> User Athena | B3: 44465314 | C3: 2026-09-14 08:30:46 | D3: NOT BAN | E3: No | F3: =COUNTIF('Results export'!$H$2:$H$202,reporting!B3) -> 1 | I3: =ROUNDUP(TODAY()-C3,0) -> 24 | J3: 0 | K3: TP | L3: protest? | N3: FP | O3: =COUNTIF($K$2:$K$16,N3) -> 3
A4: =HYPERLINK("https://sg-athena.lalamove.work/users/"&B4&"/overview?city_id=100000","User Athena") -> User Athena | B4: 45055754 | C4: 2026-10-05 15:28:58 | D4: NOT BAN | E4: No | F4: =COUNTIF('Results export'!$H$2:$H$202,reporting!B4) -> 14 | I4: =ROUNDUP(TODAY()-C4,0) -> 3 | J4: 0.029411765 | K4: TP
A5: =HYPERLINK("https://sg-athena.lalamove.work/users/"&B5&"/overview?city_id=100000","User Athena") -> User Athena | B5: 45042918 | C5: 2026-10-05 08:41:36 | D5: BANNED | E5: No | F5: =COUNTIF('Results export'!$H$2:$H$202,reporting!B5) -> 1 | G5: Placed over 20 fake orders | H5: 46301.467 | I5: =ROUNDUP(TODAY()-C5,0) -> 3 | J5: 0 | K5: TP | N5: preic | O5: =O2/(O2+O3) -> 0.8
A6: =HYPERLINK("https://sg-athena.lalamove.work/users/"&B6&"/overview?city_id=100000","User Athena") -> User Athena | B6: 44986521 | C6: 2026-10-03 08:10:46 | D6: BANNED | E6: No | F6: =COUNTIF('Results export'!$H$2:$H$202,reporting!B6) -> 93 | G6: Place over 200 fake orders | H6: 2026-10-05 10:11:24 | I6: =ROUNDUP(TODAY()-C6,0) -> 5 | J6: 0.010050251 | K6: TP
A7: =HYPERLINK("https://sg-athena.lalamove.work/users/"&B7&"/overview?city_id=100000","User Athena") -> User Athena | B7: 44464690 | C7: 2026-09-14 07:49:03 | D7: BANNED | E7: Corp | F7: =COUNTIF('Results export'!$H$2:$H$202,reporting!B7) -> 45 | G7: Placed over 400 fake orders | H7: 2026-10-01 10:11:17 | I7: =ROUNDUP(TODAY()-C7,0) -> 24 | J7: 0 | K7: TP
A8: =HYPERLINK("https://sg-athena.lalamove.work/users/"&B8&"/overview?city_id=100000","User Athena") -> User Athena | B8: 44795713 | C8: 2026-09-26 14:04:17 | D8: BANNED | E8: No | F8: =COUNTIF('Results export'!$H$2:$H$202,reporting!B8) -> 9 | G8: Placed over 50 fake orders | H8: 2026-10-01 18:32:30 | I8: =ROUNDUP(TODAY()-C8,0) -> 12 | J8: 0 | K8: TP
A9: =HYPERLINK("https://sg-athena.lalamove.work/users/"&B9&"/overview?city_id=100000","User Athena") -> User Athena | B9: 28625427 | C9: 2024-11-10 16:14:40 | D9: NOT BAN | E9: Corp | F9: =COUNTIF('Results export'!$H$2:$H$202,reporting!B9) -> 2 | I9: =ROUNDUP(TODAY()-C9,0) -> 697 | J9: 0.25950413 | K9: FP | N9: hit_rate(order)% | O9: 0.0025336541
A10: =HYPERLINK("https://sg-athena.lalamove.work/users/"&B10&"/overview?city_id=100000","User Athena") -> User Athena | B10: 44643928 | C10: 2026-09-20 19:42:34 | D10: NOT BAN | E10: No | F10: =COUNTIF('Results export'!$H$2:$H$202,reporting!B10) -> 2 | I10: =ROUNDUP(TODAY()-C10,0) -> 18 | J10: 0.088888889 | K10: TP | N10: hit_rate(user)% | O10: 0.00064233942
A11: =HYPERLINK("https://sg-athena.lalamove.work/users/"&B11&"/overview?city_id=100000","User Athena") -> User Athena | B11: 44003760 | C11: 2026-08-28 20:54:32 | D11: NOT BAN | E11: No | F11: =COUNTIF('Results export'!$H$2:$H$202,reporting!B11) -> 1 | I11: =ROUNDUP(TODAY()-C11,0) -> 41 | J11: 0.14285714 | K11: TP
A12: =HYPERLINK("https://sg-athena.lalamove.work/users/"&B12&"/overview?city_id=100000","User Athena") -> User Athena | B12: 34917006 | C12: 2025-08-29 15:36:46 | D12: NOT BAN | E12: No | F12: =COUNTIF('Results export'!$H$2:$H$202,reporting!B12) -> 4 | I12: =ROUNDUP(TODAY()-C12,0) -> 405 | J12: 0.32407407 | K12: FP | N12: hit_count(order) | O12: =SUM(F2:F16) -> 201
A13: =HYPERLINK("https://sg-athena.lalamove.work/users/"&B13&"/overview?city_id=100000","User Athena") -> User Athena | B13: 37669736 | C13: 2025-12-27 15:58:03 | D13: NOT BAN | E13: No | F13: =COUNTIF('Results export'!$H$2:$H$202,reporting!B13) -> 2 | I13: =ROUNDUP(TODAY()-C13,0) -> 285 | J13: 0.095238095 | K13: TP | N13: hit_count(user) | O13: =COUNT(B2:B16) -> 15
A14: =HYPERLINK("https://sg-athena.lalamove.work/users/"&B14&"/overview?city_id=100000","User Athena") -> User Athena | B14: 38375955 | C14: 2026-01-25 20:00:04 | D14: NOT BAN | E14: No | F14: =COUNTIF('Results export'!$H$2:$H$202,reporting!B14) -> 2 | I14: =ROUNDUP(TODAY()-C14,0) -> 256 | J14: 0 | K14: TP
A15: =HYPERLINK("https://sg-athena.lalamove.work/users/"&B15&"/overview?city_id=100000","User Athena") -> User Athena | B15: 40546651 | C15: 2026-04-21 16:48:03 | D15: NOT BAN | E15: No | F15: =COUNTIF('Results export'!$H$2:$H$202,reporting!B15) -> 1 | I15: =ROUNDUP(TODAY()-C15,0) -> 170 | J15: 0.019607843 | K15: TP
A16: =HYPERLINK("https://sg-athena.lalamove.work/users/"&B16&"/overview?city_id=100000","User Athena") -> User Athena | B16: 40007087 | C16: 2026-03-30 18:24:36 | D16: NOT BAN | E16: No | F16: =COUNTIF('Results export'!$H$2:$H$202,reporting!B16) -> 1 | I16: =ROUNDUP(TODAY()-C16,0) -> 192 | J16: 0 | K16: TP
N17: Account level
N18: Metric | O18: Strategy Observation
N19: True Positives (Accounts) | O19: 12
N20: False Positives (Accounts) | O20: 3
N21: Account Precision | O21: 80.00% (12 / 15)
N23: Order level
N24: Metric | O24: Strategy Observation
N25: Hit Rate (%) | O25: 0.00253%
N26: Hit Count (Orders) | O26: 201
N27: True Positives (Orders) | O27: =SUMIF($K$2:$K$16,N2,$F$2:$F$16) -> 172
N28: False Positives (Orders) | O28: =SUMIF($K$2:$K$16,N3,$F$2:$F$16) -> 29
N29: Order Precision | O29: 85.57% (172 / 201)
